2023-12-03 20:11:35,444 START
2023-12-03 20:11:35,444 <WSGIRequest: GET '/prefiltering/Wyniki_prefiltering/simulate_long_running_process/'>
2023-12-03 20:11:35,543 Internal Server Error: /prefiltering/Wyniki_prefiltering/simulate_long_running_process/
Traceback (most recent call last):
  File "D:\inzynierka\Aplikacji-do-generowania-rekomendacji-kontekstowych\venv\lib\site-packages\django\core\handlers\exception.py", line 55, in inner
    response = get_response(request)
  File "D:\inzynierka\Aplikacji-do-generowania-rekomendacji-kontekstowych\venv\lib\site-packages\django\core\handlers\base.py", line 197, in _get_response
    response = wrapped_callback(request, *callback_args, **callback_kwargs)
  File "D:\inzynierka\Aplikacji-do-generowania-rekomendacji-kontekstowych\venv\lib\site-packages\django\contrib\auth\decorators.py", line 23, in _wrapper_view
    return view_func(request, *args, **kwargs)
  File "D:\inzynierka\Aplikacji-do-generowania-rekomendacji-kontekstowych\Prefiltering\views.py", line 42, in simulate_long_running_process
    data = pd.read_csv(file_path)
  File "D:\inzynierka\Aplikacji-do-generowania-rekomendacji-kontekstowych\venv\lib\site-packages\pandas\io\parsers\readers.py", line 948, in read_csv
    return _read(filepath_or_buffer, kwds)
  File "D:\inzynierka\Aplikacji-do-generowania-rekomendacji-kontekstowych\venv\lib\site-packages\pandas\io\parsers\readers.py", line 617, in _read
    return parser.read(nrows)
  File "D:\inzynierka\Aplikacji-do-generowania-rekomendacji-kontekstowych\venv\lib\site-packages\pandas\io\parsers\readers.py", line 1748, in read
    ) = self._engine.read(  # type: ignore[attr-defined]
  File "D:\inzynierka\Aplikacji-do-generowania-rekomendacji-kontekstowych\venv\lib\site-packages\pandas\io\parsers\c_parser_wrapper.py", line 234, in read
    chunks = self._reader.read_low_memory(nrows)
  File "parsers.pyx", line 843, in pandas._libs.parsers.TextReader.read_low_memory
  File "parsers.pyx", line 904, in pandas._libs.parsers.TextReader._read_rows
  File "parsers.pyx", line 879, in pandas._libs.parsers.TextReader._tokenize_rows
  File "parsers.pyx", line 890, in pandas._libs.parsers.TextReader._check_tokenize_status
  File "parsers.pyx", line 2058, in pandas._libs.parsers.raise_parser_error
pandas.errors.ParserError: Error tokenizing data. C error: Expected 1 fields in line 6, saw 2

2023-12-03 20:11:46,426 START
2023-12-03 20:11:46,430 <WSGIRequest: GET '/prefiltering/Wyniki_prefiltering/simulate_long_running_process/'>
2023-12-03 20:11:46,641 Internal Server Error: /prefiltering/Wyniki_prefiltering/simulate_long_running_process/
Traceback (most recent call last):
  File "D:\inzynierka\Aplikacji-do-generowania-rekomendacji-kontekstowych\venv\lib\site-packages\django\core\handlers\exception.py", line 55, in inner
    response = get_response(request)
  File "D:\inzynierka\Aplikacji-do-generowania-rekomendacji-kontekstowych\venv\lib\site-packages\django\core\handlers\base.py", line 197, in _get_response
    response = wrapped_callback(request, *callback_args, **callback_kwargs)
  File "D:\inzynierka\Aplikacji-do-generowania-rekomendacji-kontekstowych\venv\lib\site-packages\django\contrib\auth\decorators.py", line 23, in _wrapper_view
    return view_func(request, *args, **kwargs)
  File "D:\inzynierka\Aplikacji-do-generowania-rekomendacji-kontekstowych\Prefiltering\views.py", line 42, in simulate_long_running_process
    data = pd.read_csv(file_path)
  File "D:\inzynierka\Aplikacji-do-generowania-rekomendacji-kontekstowych\venv\lib\site-packages\pandas\io\parsers\readers.py", line 948, in read_csv
    return _read(filepath_or_buffer, kwds)
  File "D:\inzynierka\Aplikacji-do-generowania-rekomendacji-kontekstowych\venv\lib\site-packages\pandas\io\parsers\readers.py", line 617, in _read
    return parser.read(nrows)
  File "D:\inzynierka\Aplikacji-do-generowania-rekomendacji-kontekstowych\venv\lib\site-packages\pandas\io\parsers\readers.py", line 1748, in read
    ) = self._engine.read(  # type: ignore[attr-defined]
  File "D:\inzynierka\Aplikacji-do-generowania-rekomendacji-kontekstowych\venv\lib\site-packages\pandas\io\parsers\c_parser_wrapper.py", line 234, in read
    chunks = self._reader.read_low_memory(nrows)
  File "parsers.pyx", line 843, in pandas._libs.parsers.TextReader.read_low_memory
  File "parsers.pyx", line 904, in pandas._libs.parsers.TextReader._read_rows
  File "parsers.pyx", line 879, in pandas._libs.parsers.TextReader._tokenize_rows
  File "parsers.pyx", line 890, in pandas._libs.parsers.TextReader._check_tokenize_status
  File "parsers.pyx", line 2058, in pandas._libs.parsers.raise_parser_error
pandas.errors.ParserError: Error tokenizing data. C error: Expected 1 fields in line 6, saw 2

2023-12-03 20:12:20,450 START
2023-12-03 20:12:20,450 <WSGIRequest: GET '/prefiltering/Wyniki_prefiltering/simulate_long_running_process/'>
2023-12-03 20:12:21,957 Index(['user\titem\tcnt\tdaytime\tweekday\tisweekend\thomework\tcost\tweather\tcountry\tcity'], dtype='object')
2023-12-03 20:12:22,101 Internal Server Error: /prefiltering/Wyniki_prefiltering/simulate_long_running_process/
Traceback (most recent call last):
  File "D:\inzynierka\Aplikacji-do-generowania-rekomendacji-kontekstowych\venv\lib\site-packages\django\core\handlers\exception.py", line 55, in inner
    response = get_response(request)
  File "D:\inzynierka\Aplikacji-do-generowania-rekomendacji-kontekstowych\venv\lib\site-packages\django\core\handlers\base.py", line 197, in _get_response
    response = wrapped_callback(request, *callback_args, **callback_kwargs)
  File "D:\inzynierka\Aplikacji-do-generowania-rekomendacji-kontekstowych\venv\lib\site-packages\django\contrib\auth\decorators.py", line 23, in _wrapper_view
    return view_func(request, *args, **kwargs)
  File "D:\inzynierka\Aplikacji-do-generowania-rekomendacji-kontekstowych\Prefiltering\views.py", line 44, in simulate_long_running_process
    rc_prefiltering = Recommender(data)
  File "D:\inzynierka\Aplikacji-do-generowania-rekomendacji-kontekstowych\utils\recommendations.py", line 11, in __init__
    self.ITEM_ID = data.columns[1]
  File "D:\inzynierka\Aplikacji-do-generowania-rekomendacji-kontekstowych\venv\lib\site-packages\pandas\core\indexes\base.py", line 5365, in __getitem__
    return getitem(key)
IndexError: index 1 is out of bounds for axis 0 with size 1
2023-12-03 20:13:34,954 START
2023-12-03 20:13:34,955 <WSGIRequest: GET '/prefiltering/Wyniki_prefiltering/simulate_long_running_process/'>
2023-12-03 20:13:34,986 Index(['User', ' Item', ' Rating', ' time:weekend', ' time:weekday',
       ' location:cinema', ' companion:family', ' companion:partner'],
      dtype='object')
2023-12-03 20:13:35,167 {'mae': 2.0555555555555554, 'rmse': 2.8382310609877335, 'recall_result': 1.0}
2023-12-03 20:13:43,180 START
2023-12-03 20:13:43,180 <WSGIRequest: GET '/prefiltering/Wyniki_prefiltering/simulate_long_running_process/'>
2023-12-03 20:13:43,188 Index(['User', ' Item', ' Rating', ' time:weekend', ' time:weekday',
       ' location:cinema', ' companion:family', ' companion:partner'],
      dtype='object')
2023-12-03 20:13:43,287 {'mae': 2.0555555555555554, 'rmse': 2.8382310609877335, 'recall_result': 1.0}
2023-12-03 20:15:09,414 Not Found: /data/download/frappe_KwarHaL.csv/
